<?xml version="1.0" encoding="UTF-8"?>
<testng-results skipped="0" failed="1" total="3" passed="2">
  <reporter-output>
  </reporter-output>
  <suite name="ReportingTests" duration-ms="52" started-at="2016-06-10T09:24:04Z" finished-at="2016-06-10T09:24:04Z">
    <groups>
    </groups>
    <test name="Basic tests" duration-ms="52" started-at="2016-06-10T09:24:04Z" finished-at="2016-06-10T09:24:04Z">
      <class name="LearnigTestNG.ReportingTests">
        <test-method status="PASS" signature="feature1()[pri:0, instance:LearnigTestNG.ReportingTests@100fc185]" name="feature1" duration-ms="19" started-at="2016-06-10T02:24:04Z" finished-at="2016-06-10T02:24:04Z">
          <reporter-output>
          </reporter-output>
        </test-method> <!-- feature1 -->
        <test-method status="PASS" signature="feature2()[pri:0, instance:LearnigTestNG.ReportingTests@100fc185]" name="feature2" duration-ms="8" started-at="2016-06-10T02:24:04Z" finished-at="2016-06-10T02:24:04Z">
          <reporter-output>
          </reporter-output>
        </test-method> <!-- feature2 -->
        <test-method status="FAIL" signature="feature3()[pri:0, instance:LearnigTestNG.ReportingTests@100fc185]" name="feature3" duration-ms="3" started-at="2016-06-10T02:24:04Z" finished-at="2016-06-10T02:24:04Z">
          <exception class="java.lang.AssertionError">
            <message>
              <![CDATA[expected [1] but found [2]]]>
            </message>
            <full-stacktrace>
              <![CDATA[java.lang.AssertionError: expected [1] but found [2]
	at org.testng.Assert.fail(Assert.java:94)
	at org.testng.Assert.failNotEquals(Assert.java:496)
	at org.testng.Assert.assertEquals(Assert.java:125)
	at org.testng.Assert.assertEquals(Assert.java:178)
	at org.testng.Assert.assertEquals(Assert.java:188)
	at LearnigTestNG.ReportingTests.feature3(ReportingTests.java:18)
	at sun.reflect.NativeMethodAccessorImpl.invoke0(Native Method)
	at sun.reflect.NativeMethodAccessorImpl.invoke(Unknown Source)
	at sun.reflect.DelegatingMethodAccessorImpl.invoke(Unknown Source)
	at java.lang.reflect.Method.invoke(Unknown Source)
	at org.testng.internal.MethodInvocationHelper.invokeMethod(MethodInvocationHelper.java:85)
	at org.testng.internal.Invoker.invokeMethod(Invoker.java:639)
	at org.testng.internal.Invoker.invokeTestMethod(Invoker.java:816)
	at org.testng.internal.Invoker.invokeTestMethods(Invoker.java:1124)
	at org.testng.internal.TestMethodWorker.invokeTestMethods(TestMethodWorker.java:125)
	at org.testng.internal.TestMethodWorker.run(TestMethodWorker.java:108)
	at org.testng.TestRunner.privateRun(TestRunner.java:774)
	at org.testng.TestRunner.run(TestRunner.java:624)
	at org.testng.SuiteRunner.runTest(SuiteRunner.java:359)
	at org.testng.SuiteRunner.runSequentially(SuiteRunner.java:354)
	at org.testng.SuiteRunner.privateRun(SuiteRunner.java:312)
	at org.testng.SuiteRunner.run(SuiteRunner.java:261)
	at org.testng.SuiteRunnerWorker.runSuite(SuiteRunnerWorker.java:52)
	at org.testng.SuiteRunnerWorker.run(SuiteRunnerWorker.java:86)
	at org.testng.TestNG.runSuitesSequentially(TestNG.java:1215)
	at org.testng.TestNG.runSuitesLocally(TestNG.java:1140)
	at org.testng.TestNG.run(TestNG.java:1048)
	at org.testng.remote.AbstractRemoteTestNG.run(AbstractRemoteTestNG.java:126)
	at org.testng.remote.RemoteTestNG.initAndRun(RemoteTestNG.java:137)
	at org.testng.remote.RemoteTestNG.main(RemoteTestNG.java:58)
]]>
            </full-stacktrace>
          </exception> <!-- java.lang.AssertionError -->
          <reporter-output>
          </reporter-output>
        </test-method> <!-- feature3 -->
      </class> <!-- LearnigTestNG.ReportingTests -->
    </test> <!-- Basic tests -->
  </suite> <!-- ReportingTests -->
</testng-results>
